Workbook

Sheet Dex
A1: Pokemon | B1: Name in file | C1: Sprite
A2: None | B2: none | C2: =(IMAGE("https://gcdn.thunderstore.io/live/repository/icons/UnknownMystery-MysteryModpack-1.0.0.png.128x128_q95.png", 1))
A3: Bulbasaur | B3: bulbasaur | C3: =(IMAGE("https://play.pokemonshowdown.com/sprites/gen5/"&B3&".png", 3))
A4: Ivysaur | B4: ivysaur | C4: =(IMAGE("https://play.pokemonshowdown.com/sprites/gen5/"&B4&".png", 3))
A5: Venusaur | B5: =LOWER(A5) -> venusaur | C5: =(IMAGE("https://play.pokemonshowdown.com/sprites/gen5/"&B5&".png", 3))
A6: Venusaur-Gmax | B6: =LOWER(A6) -> venusaur-gmax | C6: =(IMAGE("https://play.pokemonshowdown.com/sprites/gen5/"&B6&".png", 3))
A7: Venusaur-Mega | B7: =LOWER(A7) -> venusaur-mega | C7: =(IMAGE("https://play.pokemonshowdown.com/sprites/gen5/"&B7&".png", 3))
A8: Charmander | B8: =LOWER(A8) -> charmander | C8: =(IMAGE("https://play.pokemonshowdown.com/sprites/gen5/"&B8&".png", 3))
A9: Charmeleon | B9: charmeleon | C9: =(IMAGE("https://play.pokemonshowdown.com/sprites/gen5/"&B9&".png", 3))
A10: Charizard | B10: charizard | C10: =(IMAGE("https://play.pokemonshowdown.com/sprites/gen5/"&B10&".png", 3))
A11: Charizard-Gmax | B11: =LOWER(A11) -> charizard-gmax | C11: =(IMAGE("https://play.pokemonshowdown.com/sprites/gen5/"&B11&".png", 3))
A12: Charizard-Mega-X | B12: charizard-megax | C12: =(IMAGE("https://play.pokemonshowdown.com/sprites/gen5/"&B12&".png", 3))
A13: Charizard-Mega-Y | B13: charizard-megay | C13: =(IMAGE("https://play.pokemonshowdown.com/sprites/gen5/"&B13&".png", 3))
A14: Squirtle | B14: =LOWER(A14) -> squirtle | C14: =(IMAGE("https://play.pokemonshowdown.com/sprites/gen5/"&B14&".png", 3))
A15: Wartortle | B15: =LOWER(A15) -> wartortle | C15: =(IMAGE("https://play.pokemonshowdown.com/sprites/gen5/"&B15&".png", 3))
A16: Blastoise | B16: =LOWER(A16) -> blastoise | C16: =(IMAGE("https://play.pokemonshowdown.com/sprites/gen5/"&B16&".png", 3))
A17: Blastoise-Gmax | B17: =LOWER(A17) -> blastoise-gmax | C17: =(IMAGE("https://play.pokemonshowdown.com/sprites/gen5/"&B17&".png", 3))
A18: Blastoise-Mega | B18: =LOWER(A18) -> blastoise-mega | C18: =(IMAGE("https://play.pokemonshowdown.com/sprites/gen5/"&B18&".png", 3))
A19: Caterpie | B19: =LOWER(A19) -> caterpie | C19: =(IMAGE("https://play.pokemonshowdown.com/sprites/gen5/"&B19&".png", 3))
A20: Metapod | B20: =LOWER(A20) -> metapod | C20: =(IMAGE("https://play.pokemonshowdown.com/sprites/gen5/"&B20&".png", 3))
A21: Butterfree | B21: =LOWER(A21) -> butterfree | C21: =(IMAGE("https://play.pokemonshowdown.com/sprites/gen5/"&B21&".png", 3))
A22: Butterfree-Gmax | B22: =LOWER(A22) -> butterfree-gmax | C22: =(IMAGE("https://play.pokemonshowdown.com/sprites/gen5/"&B22&".png", 3))
A23: Weedle | B23: =LOWER(A23) -> weedle | C23: =(IMAGE("https://play.pokemonshowdown.com/sprites/gen5/"&B23&".png", 3))
A24: Kakuna | B24: =LOWER(A24) -> kakuna | C24: =(IMAGE("https://play.pokemonshowdown.com/sprites/gen5/"&B24&".png", 3))
A25: Beedrill | B25: =LOWER(A25) -> beedrill | C25: =(IMAGE("https://play.pokemonshowdown.com/sprites/gen5/"&B25&".png", 3))
... A39: Pikachu | B39: =LOWER(A39) -> pikachu | C39: =(IMAGE("https://play.pokemonshowdown.com/sprites/gen5/"&B39&".png", 3))
A40: Pikachu-Partner | B40: pikachu-partner | C40: =(IMAGE("https://play.pokemonshowdown.com/sprites/gen5/"&B40&".png", 3))
A41: Pikachu-Gmax | B41: =LOWER(A41) -> pikachu-gmax | C41: =(IMAGE("https://play.pokemonshowdown.com/sprites/gen5/"&B41&".png", 3))
A42: Raichu | B42: =LOWER(A42) -> raichu | C42: =(IMAGE("https://play.pokemonshowdown.com/sprites/gen5/"&B42&".png", 3))
A43: Raichu-Mega-X | B43: raichu-megax | C43: =(IMAGE("https://pokedoku-space.nyc3.cdn.digitaloceanspaces.com/resources/pokemon/10304.png", 3))
A44: Raichu-Mega-Y | B44: raichu-megay | C44: =(IMAGE("https://pokedoku-space.nyc3.cdn.digitaloceanspaces.com/resources/pokemon/10305.png", 3))
A45: Raichu-Alola | B45: =LOWER(A45) -> raichu-alola | C45: =(IMAGE("https://play.pokemonshowdown.com/sprites/gen5/"&B45&".png", 3))
A46: Sandshrew | B46: =LOWER(A46) -> sandshrew | C46: =(IMAGE("https://play.pokemonshowdown.com/sprites/gen5/"&B46&".png", 3))
A47: Sandshrew-Alola | B47: =LOWER(A47) -> sandshrew-alola | C47: =(IMAGE("https://play.pokemonshowdown.com/sprites/gen5/"&B47&".png", 3))
A48: Sandslash | B48: =LOWER(A48) -> sandslash | C48: =(IMAGE("https://play.pokemonshowdown.com/sprites/gen5/"&B48&".png", 3))
A49: Sandslash-Alola | B49: =LOWER(A49) -> sandslash-alola | C49: =(IMAGE("https://play.pokemonshowdown.com/sprites/gen5/"&B49&".png", 3))
A50: Nidoran-F | B50: nidoranf | C50: =(IMAGE("https://play.pokemonshowdown.com/sprites/gen5/"&B50&".png", 3))
A51: Nidorina | B51: =LOWER(A51) -> nidorina | C51: =(IMAGE("https://play.pokemonshowdown.com/sprites/gen5/"&B51&".png", 3))
A52: Nidoqueen | B52: =LOWER(A52) -> nidoqueen | C52: =(IMAGE("https://play.pokemonshowdown.com/sprites/gen5/"&B52&".png", 3))
A53: Nidoran-M | B53: nidoranm | C53: =(IMAGE("https://play.pokemonshowdown.com/sprites/gen5/"&B53&".png", 3))
...

Sheet Sprites
A1: TRAINER_PIC_AQUA_ADMIN_F
A2: TRAINER_PIC_AQUA_ADMIN_M
A3: TRAINER_PIC_AQUA_GRUNT_F
A4: TRAINER_PIC_AQUA_GRUNT_M
A5: TRAINER_PIC_AQUA_LEADER_ARCHIE
A6: TRAINER_PIC_GRETA
A7: TRAINER_PIC_AROMA_LADY
A8: TRAINER_PIC_BATTLE_GIRL
A9: TRAINER_PIC_BEAUTY
A10: TRAINER_PIC_BIRD_KEEPER
A11: TRAINER_PIC_BLACK_BELT
A12: TRAINER_PIC_BRENDAN
... A108: TRAINER_PIC_CLAIR

Sheet Roxanne Split
A2: Route 103
A3: Name | B3: Route 103 Rival
A4: Pokémon | B4: {=iferror(VLOOKUP(INDIRECT(ADDRESS(ROW()+1,COLUMN(), 4)),Dex!$A$2:$C262,3,false),"")} | C4: {=iferror(VLOOKUP(INDIRECT(ADDRESS(ROW()+1,COLUMN(), 4)),Dex!$A$2:$C262,3,false),"")} | D4: {=iferror(VLOOKUP(INDIRECT(ADDRESS(ROW()+1,COLUMN(), 4)),Dex!$A$2:$C262,3,false),"")} | E4: {=iferror(VLOOKUP(INDIRECT(ADDRESS(ROW()+1,COLUMN(), 4)),Dex!$A$2:$C262,3,false),"")} | F4: {=iferror(VLOOKUP(INDIRECT(ADDRESS(ROW()+1,COLUMN(), 4)),Dex!$A$2:$C262,3,false),"")} | G4: {=iferror(VLOOKUP(INDIRECT(ADDRESS(ROW()+1,COLUMN(), 4)),Dex!$A$2:$C262,3,false),"")} | H4: {=iferror(VLOOKUP("TRAINER_PIC_Brendan",Sprites!$A$1:$B262,2,false),"")}
B5: Oshawott | C5: Litten | D5: Riolu
A6: Level | B6: 10 | C6: 10 | D6: 11
A7: Held Item | B7: Oran Berry | C7: Oran Berry | D7: Berry Juice
A8: Ability | B8: Torrent | C8: Intimidate | D8: Prankster
A9: Nature | B9: Hasty | C9: Adamant | D9: Jolly
A10: Moves | B10: Chilling Water | C10: Fake Out | D10: Mach Punch
B11: Razor Shell | C11: Flame Charge | D11: Metal Claw
B12: Grass Knot | C12: Trailblaze | D12: Copycat
B13: Encore | C13: Torment
A14: Root Academy
A15: Name | B15: Youngster Ren
A16: Pokémon | B16: {=iferror(VLOOKUP(INDIRECT(ADDRESS(ROW()+1,COLUMN(), 4)),Dex!$A$2:$C262,3,false),"")} | C16: {=iferror(VLOOKUP(INDIRECT(ADDRESS(ROW()+1,COLUMN(), 4)),Dex!$A$2:$C262,3,false),"")} | D16: {=iferror(VLOOKUP(INDIRECT(ADDRESS(ROW()+1,COLUMN(), 4)),Dex!$A$2:$C262,3,false),"")} | E16: {=iferror(VLOOKUP(INDIRECT(ADDRESS(ROW()+1,COLUMN(), 4)),Dex!$A$2:$C262,3,false),"")} | F16: {=iferror(VLOOKUP(INDIRECT(ADDRESS(ROW()+1,COLUMN(), 4)),Dex!$A$2:$C262,3,false),"")} | G16: {=iferror(VLOOKUP(INDIRECT(ADDRESS(ROW()+1,COLUMN(), 4)),Dex!$A$2:$C262,3,false),"")} | H16: {=iferror(VLOOKUP("TRAINER_PIC_Youngster",Sprites!$A$1:$B262,2,false),"")}
B17: None
A18: Level | B18: 0
A19: Held Item | B19: None
A20: Ability | B20: None
A21: Nature | B21: Hardy
A22: Moves | B22: None
A26: Name | B26: Youngster Levi
A27: Pokémon | B27: {=iferror(VLOOKUP(INDIRECT(ADDRESS(ROW()+1,COLUMN(), 4)),Dex!$A$2:$C262,3,false),"")} | C27: {=iferror(VLOOKUP(INDIRECT(ADDRESS(ROW()+1,COLUMN(), 4)),Dex!$A$2:$C262,3,false),"")} | D27: {=iferror(VLOOKUP(INDIRECT(ADDRESS(ROW()+1,COLUMN(), 4)),Dex!$A$2:$C262,3,false),"")} | E27: {=iferror(VLOOKUP(INDIRECT(ADDRESS(ROW()+1,COLUMN(), 4)),Dex!$A$2:$C262,3,false),"")} | F27: {=iferror(VLOOKUP(INDIRECT(ADDRESS(ROW()+1,COLUMN(), 4)),Dex!$A$2:$C262,3,false),"")} | G27: {=iferror(VLOOKUP(INDIRECT(ADDRESS(ROW()+1,COLUMN(), 4)),Dex!$A$2:$C262,3,false),"")} | H27: {=iferror(VLOOKUP("TRAINER_PIC_Youngster",Sprites!$A$1:$B262,2,false),"")}
B28: None
A29: Level | B29: 0
A30: Held Item | B30: None
A31: Ability | B31: None
A32: Nature | B32: Hardy
A33: Moves | B33: None
A37: Name | B37: Lass Videl
A38: Pokémon | B38: {=iferror(VLOOKUP(INDIRECT(ADDRESS(ROW()+1,COLUMN(), 4)),Dex!$A$2:$C262,3,false),"")} | C38: {=iferror(VLOOKUP(INDIRECT(ADDRESS(ROW()+1,COLUMN(), 4)),Dex!$A$2:$C262,3,false),"")} | D38: {=iferror(VLOOKUP(INDIRECT(ADDRESS(ROW()+1,COLUMN(), 4)),Dex!$A$2:$C262,3,false),"")} | E38: {=iferror(VLOOKUP(INDIRECT(ADDRESS(ROW()+1,COLUMN(), 4)),Dex!$A$2:$C262,3,false),"")} | F38: {=iferror(VLOOKUP(INDIRECT(ADDRESS(ROW()+1,COLUMN(), 4)),Dex!$A$2:$C262,3,false),"")} | G38: {=iferror(VLOOKUP(INDIRECT(ADDRESS(ROW()+1,COLUMN(), 4)),Dex!$A$2:$C262,3,false),"")} | H38: {=iferror(VLOOKUP("TRAINER_PIC_Lass",Sprites!$A$1:$B262,2,false),"")}
B39: None
A40: Level | B40: 0
A41: Held Item | B41: None
A42: Ability | B42: None
A43: Nature | B43: Hardy
A44: Moves | B44: None
A48: Name | B48: Youngster Itachi
A49: Pokémon | B49: {=iferror(VLOOKUP(INDIRECT(ADDRESS(ROW()+1,COLUMN(), 4)),Dex!$A$2:$C262,3,false),"")} | C49: {=iferror(VLOOKUP(INDIRECT(ADDRESS(ROW()+1,COLUMN(), 4)),Dex!$A$2:$C262,3,false),"")} | D49: {=iferror(VLOOKUP(INDIRECT(ADDRESS(ROW()+1,COLUMN(), 4)),Dex!$A$2:$C262,3,false),"")} | E49: {=iferror(VLOOKUP(INDIRECT(ADDRESS(ROW()+1,COLUMN(), 4)),Dex!$A$2:$C262,3,false),"")} | F49: {=iferror(VLOOKUP(INDIRECT(ADDRESS(ROW()+1,COLUMN(), 4)),Dex!$A$2:$C262,3,false),"")} | G49: {=iferror(VLOOKUP(INDIRECT(ADDRESS(ROW()+1,COLUMN(), 4)),Dex!$A$2:$C262,3,false),"")} | H49: {=iferror(VLOOKUP("TRAINER_PIC_Youngster",Sprites!$A$1:$B262,2,false),"")}
B50: None
...

Sheet Brawly Split
A2: Route 116
A3: Name | B3: Youngster Schmo
A4: Pokémon | B4: {=iferror(VLOOKUP(INDIRECT(ADDRESS(ROW()+1,COLUMN(), 4)),Dex!$A$2:$C205,3,false),"")} | C4: {=iferror(VLOOKUP(INDIRECT(ADDRESS(ROW()+1,COLUMN(), 4)),Dex!$A$2:$C205,3,false),"")} | D4: {=iferror(VLOOKUP(INDIRECT(ADDRESS(ROW()+1,COLUMN(), 4)),Dex!$A$2:$C205,3,false),"")} | E4: {=iferror(VLOOKUP(INDIRECT(ADDRESS(ROW()+1,COLUMN(), 4)),Dex!$A$2:$C205,3,false),"")} | F4: {=iferror(VLOOKUP(INDIRECT(ADDRESS(ROW()+1,COLUMN(), 4)),Dex!$A$2:$C205,3,false),"")} | G4: {=iferror(VLOOKUP(INDIRECT(ADDRESS(ROW()+1,COLUMN(), 4)),Dex!$A$2:$C205,3,false),"")} | H4: {=iferror(VLOOKUP("TRAINER_PIC_Youngster",Sprites!$A$1:$B205,2,false),"")}
B5: Pidgeot | C5: Linoone | D5: Wigglytuff
A6: Level | B6: 39 | C6: 40 | D6: 40
A7: Held Item | B7: Wacan Berry | C7: Iapapa Berry | D7: Life Orb
A8: Ability | B8: Keen Eye | C8: Gluttony | D8: Competitive
A9: Nature | B9: Hasty | C9: Adamant | D9: Modest
A10: Moves | B10: Mirror Move | C10: Belly Drum | D10: Dazzling Gleam
B11: Air Slash | C11: Extreme Speed | D11: Ice Beam
B12: Heat Wave | C12: Seed Bomb | D12: Thunderbolt
B13: Steel Wing | C13: Stomping Tantrum | D13: Flamethrower
A14: Name | B14: Bug Catcher Jose
A15: Pokémon | B15: {=iferror(VLOOKUP(INDIRECT(ADDRESS(ROW()+1,COLUMN(), 4)),Dex!$A$2:$C205,3,false),"")} | C15: {=iferror(VLOOKUP(INDIRECT(ADDRESS(ROW()+1,COLUMN(), 4)),Dex!$A$2:$C205,3,false),"")} | D15: {=iferror(VLOOKUP(INDIRECT(ADDRESS(ROW()+1,COLUMN(), 4)),Dex!$A$2:$C205,3,false),"")} | E15: {=iferror(VLOOKUP(INDIRECT(ADDRESS(ROW()+1,COLUMN(), 4)),Dex!$A$2:$C205,3,false),"")} | F15: {=iferror(VLOOKUP(INDIRECT(ADDRESS(ROW()+1,COLUMN(), 4)),Dex!$A$2:$C205,3,false),"")} | G15: {=iferror(VLOOKUP(INDIRECT(ADDRESS(ROW()+1,COLUMN(), 4)),Dex!$A$2:$C205,3,false),"")} | H15: {=iferror(VLOOKUP("TRAINER_PIC_Bug_Catcher",Sprites!$A$1:$B205,2,false),"")}
B16: Venomoth | C16: Wormadam-Sandy | D16: Gastrodon | E16: Kleavor
A17: Level | B17: 40 | C17: 40 | D17: 41 | E17: 42
A18: Held Item | B18: Lum Berry | C18: Occa Berry | D18: Rindo Berry | E18: Rock Gem
A19: Ability | B19: Tinted Lens | C19: Anticipation | D19: Storm Drain | E19: Sheer Force
A20: Nature | B20: Modest | C20: Adamant | D20: Modest | E20: Jolly
A21: Moves | B21: Sludge Bomb | C21: Earthquake | D21: Earth Power | E21: Morning Sun
B22: Bug Buzz | C22: Stealth Rock | D22: Scald | E22: Stone Edge
B23: Sleep Powder | C23: Sucker Punch | D23: Recover | E23: Lunge
B24: Quiver Dance | C24: Rock Tomb | D24: Ice Beam | E24: Brick Break
A25: Name | B25: School Kid Karen
A26: Pokémon | B26: {=iferror(VLOOKUP(INDIRECT(ADDRESS(ROW()+1,COLUMN(), 4)),Dex!$A$2:$C205,3,false),"")} | C26: {=iferror(VLOOKUP(INDIRECT(ADDRESS(ROW()+1,COLUMN(), 4)),Dex!$A$2:$C205,3,false),"")} | D26: {=iferror(VLOOKUP(INDIRECT(ADDRESS(ROW()+1,COLUMN(), 4)),Dex!$A$2:$C205,3,false),"")} | E26: {=iferror(VLOOKUP(INDIRECT(ADDRESS(ROW()+1,COLUMN(), 4)),Dex!$A$2:$C205,3,false),"")} | F26: {=iferror(VLOOKUP(INDIRECT(ADDRESS(ROW()+1,COLUMN(), 4)),Dex!$A$2:$C205,3,false),"")} | G26: {=iferror(VLOOKUP(INDIRECT(ADDRESS(ROW()+1,COLUMN(), 4)),Dex!$A$2:$C205,3,false),"")} | H26: {=iferror(VLOOKUP("TRAINER_PIC_School_Kid_F",Sprites!$A$1:$B205,2,false),"")}
B27: Primeape | C27: Ursaring | D27: Throh | E27: Magneton
A28: Level | B28: 40 | C28: 41 | D28: 41 | E28: 41
A29: Held Item | B29: Eviolite | C29: Toxic Orb | D29: Flame Orb | E29: Sitrus Berry
A30: Ability | B30: Anger Point | C30: Quick Feet | D30: Guts | E30: Analytic
A31: Nature | B31: Adamant | C31: Brave | D31: Adamant | E31: Modest
A32: Moves | B32: Drain Punch | C32: Secret Power | D32: Protect | E32: Thunderbolt
B33: Substitute | C33: Throat Chop | D33: Stone Edge | E33: Flash Cannon
B34: Rage Fist | C34: Last Resort | D34: Superpower | E34: Hidden Power Grass
B35: Bulk Up | C35: Protect | D35: Knock Off | E35: Magnet Rise
A36: Name | B36: Hiker Clark & Youngster Johnson [Double]
A37: Pokémon | B37: {=iferror(VLOOKUP(INDIRECT(ADDRESS(ROW()+1,COLUMN(), 4)),Dex!$A$2:$C205,3,false),"")} | C37: {=iferror(VLOOKUP(INDIRECT(ADDRESS(ROW()+1,COLUMN(), 4)),Dex!$A$2:$C205,3,false),"")} | D37: {=iferror(VLOOKUP(INDIRECT(ADDRESS(ROW()+1,COLUMN(), 4)),Dex!$A$2:$C205,3,false),"")} | E37: {=iferror(VLOOKUP(INDIRECT(ADDRESS(ROW()+1,COLUMN(), 4)),Dex!$A$2:$C205,3,false),"")} | F37: {=iferror(VLOOKUP(INDIRECT(ADDRESS(ROW()+1,COLUMN(), 4)),Dex!$A$2:$C205,3,false),"")} | G37: {=iferror(VLOOKUP(INDIRECT(ADDRESS(ROW()+1,COLUMN(), 4)),Dex!$A$2:$C205,3,false),"")} | H37: {=iferror(VLOOKUP("TRAINER_PIC_Hiker",Sprites!$A$1:$B205,2,false),"")}
B38: Golem | C38: Sandslash | E38: Persian | F38: Chimecho
A39: Level | B39: 42 | C39: 41 | E39: 41 | F39: 41
A40: Held Item | B40: Lum Berry | C40: Sitrus Berry | E40: Loaded Dice | F40: Blunder Policy
A41: Ability | B41: Sturdy | C41: Sand Rush | E41: Technician | F41: Levitate
...

Sheet Wattson Split
A2: Route 109
A3: Name | B3: Tuber Hailey
A4: Pokémon | B4: {=iferror(VLOOKUP(INDIRECT(ADDRESS(ROW()+1,COLUMN(), 4)),Dex!$A$2:$C294,3,false),"")} | C4: {=iferror(VLOOKUP(INDIRECT(ADDRESS(ROW()+1,COLUMN(), 4)),Dex!$A$2:$C294,3,false),"")} | D4: {=iferror(VLOOKUP(INDIRECT(ADDRESS(ROW()+1,COLUMN(), 4)),Dex!$A$2:$C294,3,false),"")} | E4: {=iferror(VLOOKUP(INDIRECT(ADDRESS(ROW()+1,COLUMN(), 4)),Dex!$A$2:$C294,3,false),"")} | F4: {=iferror(VLOOKUP(INDIRECT(ADDRESS(ROW()+1,COLUMN(), 4)),Dex!$A$2:$C294,3,false),"")} | G4: {=iferror(VLOOKUP(INDIRECT(ADDRESS(ROW()+1,COLUMN(), 4)),Dex!$A$2:$C294,3,false),"")} | H4: {=iferror(VLOOKUP("TRAINER_PIC_Tuber_F",Sprites!$A$1:$B294,2,false),"")}
B5: Stunfisk-Galar | C5: Carnivine | D5: Mothim | E5: Wugtrio
A6: Level | B6: 46 | C6: 47 | D6: 47 | E6: 47
A7: Held Item | B7: Chople Berry | C7: Binding Band | D7: Focus Sash | E7: Muscle Band
A8: Ability | B8: Mimicry | C8: Levitate | D8: Swarm | E8: Arena Trap
A9: Nature | B9: Sassy | C9: Adamant | D9: Timid | E9: Adamant
A10: Moves | B10: Stealth Rock | C10: Snap Trap | D10: Sleep Powder | E10: Aqua Cutter
B11: Snap Trap | C11: Sleep Powder | D11: Quiver Dance | E11: Final Gambit
B12: Thunder Wave | C12: Stun Spore | D12: Air Slash | E12: Foul Play
B13: Earthquake | C13: Crunch | D13: Bug Buzz | E13: Aqua Jet
A14: Name | B14: Tuber Ricky
A15: Pokémon | B15: {=iferror(VLOOKUP(INDIRECT(ADDRESS(ROW()+1,COLUMN(), 4)),Dex!$A$2:$C294,3,false),"")} | C15: {=iferror(VLOOKUP(INDIRECT(ADDRESS(ROW()+1,COLUMN(), 4)),Dex!$A$2:$C294,3,false),"")} | D15: {=iferror(VLOOKUP(INDIRECT(ADDRESS(ROW()+1,COLUMN(), 4)),Dex!$A$2:$C294,3,false),"")} | E15: {=iferror(VLOOKUP(INDIRECT(ADDRESS(ROW()+1,COLUMN(), 4)),Dex!$A$2:$C294,3,false),"")} | F15: {=iferror(VLOOKUP(INDIRECT(ADDRESS(ROW()+1,COLUMN(), 4)),Dex!$A$2:$C294,3,false),"")} | G15: {=iferror(VLOOKUP(INDIRECT(ADDRESS(ROW()+1,COLUMN(), 4)),Dex!$A$2:$C294,3,false),"")} | H15: {=iferror(VLOOKUP("TRAINER_PIC_Tuber_M",Sprites!$A$1:$B294,2,false),"")}
B16: Pincurchin | C16: Simisage | D16: Raichu-Alola | E16: Clawitzer
A17: Level | B17: 47 | C17: 47 | D17: 47 | E17: 47
A18: Held Item | B18: Mental Herb | C18: Eject Pack | D18: Water Gem | E18: Electric Seed
A19: Ability | B19: Electric Surge | C19: Overgrow | D19: Surge Surfer | E19: Mega Launcher
A20: Nature | B20: Sassy | C20: Timid | D20: Modest | E20: Calm
A21: Moves | B21: Spikes | C21: Nature Power | D21: Fake Tears | E21: Water Pulse
B22: Toxic Spikes | C22: Leaf Storm | D22: Rising Voltage | E22: Terrain Pulse
B23: Memento | C23: Focus Blast | D23: Surf | E23: Dark Pulse
B24: Liquidation | C24: Grass Knot | D24: Volt Switch | E24: Aura Sphere
A25: Name | B25: Tuber Lola
A26: Pokémon | B26: {=iferror(VLOOKUP(INDIRECT(ADDRESS(ROW()+1,COLUMN(), 4)),Dex!$A$2:$C294,3,false),"")} | C26: {=iferror(VLOOKUP(INDIRECT(ADDRESS(ROW()+1,COLUMN(), 4)),Dex!$A$2:$C294,3,false),"")} | D26: {=iferror(VLOOKUP(INDIRECT(ADDRESS(ROW()+1,COLUMN(), 4)),Dex!$A$2:$C294,3,false),"")} | E26: {=iferror(VLOOKUP(INDIRECT(ADDRESS(ROW()+1,COLUMN(), 4)),Dex!$A$2:$C294,3,false),"")} | F26: {=iferror(VLOOKUP(INDIRECT(ADDRESS(ROW()+1,COLUMN(), 4)),Dex!$A$2:$C294,3,false),"")} | G26: {=iferror(VLOOKUP(INDIRECT(ADDRESS(ROW()+1,COLUMN(), 4)),Dex!$A$2:$C294,3,false),"")} | H26: {=iferror(VLOOKUP("TRAINER_PIC_Tuber_F",Sprites!$A$1:$B294,2,false),"")}
B27: Aromatisse | C27: Marowak | D27: Veluza | E27: Machamp
A28: Level | B28: 48 | C28: 47 | D28: 47 | E28: 48
A29: Held Item | B29: Iapapa Berry | C29: Thick Club | D29: Sitrus Berry | E29: Ability Shield
A30: Ability | B30: Aroma Veil | C30: Battle Armor | D30: Sharpness | E30: No Guard
A31: Nature | B31: Quiet | C31: Brave | D31: Brave | E31: Brave
A32: Moves | B32: Trick Room | C32: Bone Rush | D32: Trick Room | E32: Dynamic Punch
B33: Nasty Plot | C33: Rock Slide | D33: Psycho Cut | E33: Rock Slide
B34: Moonblast | C34: Power-Up Punch | D34: Aqua Cutter | E34: Ice Punch
B35: Mystical Fire | C35: Thunder Punch | D35: Fillet Away | E35: Throat Chop
A36: Name | B36: Sailor Edmond
A37: Pokémon | B37: {=iferror(VLOOKUP(INDIRECT(ADDRESS(ROW()+1,COLUMN(), 4)),Dex!$A$2:$C294,3,false),"")} | C37: {=iferror(VLOOKUP(INDIRECT(ADDRESS(ROW()+1,COLUMN(), 4)),Dex!$A$2:$C294,3,false),"")} | D37: {=iferror(VLOOKUP(INDIRECT(ADDRESS(ROW()+1,COLUMN(), 4)),Dex!$A$2:$C294,3,false),"")} | E37: {=iferror(VLOOKUP(INDIRECT(ADDRESS(ROW()+1,COLUMN(), 4)),Dex!$A$2:$C294,3,false),"")} | F37: {=iferror(VLOOKUP(INDIRECT(ADDRESS(ROW()+1,COLUMN(), 4)),Dex!$A$2:$C294,3,false),"")} | G37: {=iferror(VLOOKUP(INDIRECT(ADDRESS(ROW()+1,COLUMN(), 4)),Dex!$A$2:$C294,3,false),"")} | H37: {=iferror(VLOOKUP("TRAINER_PIC_Sailor",Sprites!$A$1:$B294,2,false),"")}
B38: Masquerain | C38: Dachsbun | D38: Purugly | E38: Druddigon
A39: Level | B39: 47 | C39: 47 | D39: 47 | E39: 48
A40: Held Item | B40: Silver Powder | C40: Lum Berry | D40: Adrenaline Orb | E40: Life Orb
A41: Ability | B41: Intimidate | C41: Well-Baked Body | D41: Defiant | E41: Sheer Force
...

Sheet Norman Split
A2: Land Cave
A3: Name | B3: Land Cave Team Magma Grunt #1
A4: Pokémon | B4: {=iferror(VLOOKUP(INDIRECT(ADDRESS(ROW()+1,COLUMN(), 4)),Dex!$A$2:$C449,3,false),"")} | C4: {=iferror(VLOOKUP(INDIRECT(ADDRESS(ROW()+1,COLUMN(), 4)),Dex!$A$2:$C449,3,false),"")} | D4: {=iferror(VLOOKUP(INDIRECT(ADDRESS(ROW()+1,COLUMN(), 4)),Dex!$A$2:$C449,3,false),"")} | E4: {=iferror(VLOOKUP(INDIRECT(ADDRESS(ROW()+1,COLUMN(), 4)),Dex!$A$2:$C449,3,false),"")} | F4: {=iferror(VLOOKUP(INDIRECT(ADDRESS(ROW()+1,COLUMN(), 4)),Dex!$A$2:$C449,3,false),"")} | G4: {=iferror(VLOOKUP(INDIRECT(ADDRESS(ROW()+1,COLUMN(), 4)),Dex!$A$2:$C449,3,false),"")} | H4: {=iferror(VLOOKUP("TRAINER_PIC_Magma_Grunt_F",Sprites!$A$1:$B449,2,false),"")}
B5: Rapidash | C5: Lilligant | D5: Talonflame | E5: Tropius
A6: Level | B6: 60 | C6: 61 | D6: 61 | E6: 61
A7: Held Item | B7: Heat Rock | C7: Grass Gem | D7: Heat Rock | E7: Bright Powder
A8: Ability | B8: Flame Body | C8: Chlorophyll | D8: Flame Body | E8: Chlorophyll
A9: Nature | B9: Jolly | C9: Modest | D9: Jolly | E9: Adamant
A10: Moves | B10: Sunny Day | C10: Solar Beam | D10: Blaze Kick | E10: Earthquake
B11: Flare Blitz | C11: Weather Ball | D11: Dual Wingbeat | E11: Dragon Dance
B12: High Horsepower | C12: Grass Whistle | D12: Swords Dance | E12: Solar Blade
B13: Will-O-Wisp | C13: Dream Eater | D13: Sunny Day | E13: Dual Wingbeat
A14: Name | B14: Team Magma Grunt Croven
A15: Pokémon | B15: {=iferror(VLOOKUP(INDIRECT(ADDRESS(ROW()+1,COLUMN(), 4)),Dex!$A$2:$C449,3,false),"")} | C15: {=iferror(VLOOKUP(INDIRECT(ADDRESS(ROW()+1,COLUMN(), 4)),Dex!$A$2:$C449,3,false),"")} | D15: {=iferror(VLOOKUP(INDIRECT(ADDRESS(ROW()+1,COLUMN(), 4)),Dex!$A$2:$C449,3,false),"")} | E15: {=iferror(VLOOKUP(INDIRECT(ADDRESS(ROW()+1,COLUMN(), 4)),Dex!$A$2:$C449,3,false),"")} | F15: {=iferror(VLOOKUP(INDIRECT(ADDRESS(ROW()+1,COLUMN(), 4)),Dex!$A$2:$C449,3,false),"")} | G15: {=iferror(VLOOKUP(INDIRECT(ADDRESS(ROW()+1,COLUMN(), 4)),Dex!$A$2:$C449,3,false),"")} | H15: {=iferror(VLOOKUP("TRAINER_PIC_Magma_Grunt_M",Sprites!$A$1:$B449,2,false),"")}
B16: Torkoal | C16: Exeggutor | D16: Centiskorch | E16: Togekiss
A17: Level | B17: 61 | C17: 61 | D17: 62 | E17: 62
A18: Held Item | B18: Heat Rock | C18: Focus Band | D18: Leftovers | E18: Scope Lens
A19: Ability | B19: Drought | C19: Chlorophyll | D19: Flash Fire | E19: Super Luck
A20: Nature | B20: Modest | C20: Timid | D20: Adamant | E20: Timid
A21: Moves | B21: Stealth Rock | C21: Solar Beam | D21: Coil | E21: Flamethrower
B22: Explosion | C22: Psychic | D22: Leech Life | E22: Morning Sun
B23: Flamethrower | C23: Sunny Day | D23: Fire Lash | E23: Air Cutter
B24: Solar Beam | C24: Explosion | D24: Power Whip | E24: Aura Sphere
A25: Name | B25: Land Cave Team Magma Grunt #3
A26: Pokémon | B26: {=iferror(VLOOKUP(INDIRECT(ADDRESS(ROW()+1,COLUMN(), 4)),Dex!$A$2:$C449,3,false),"")} | C26: {=iferror(VLOOKUP(INDIRECT(ADDRESS(ROW()+1,COLUMN(), 4)),Dex!$A$2:$C449,3,false),"")} | D26: {=iferror(VLOOKUP(INDIRECT(ADDRESS(ROW()+1,COLUMN(), 4)),Dex!$A$2:$C449,3,false),"")} | E26: {=iferror(VLOOKUP(INDIRECT(ADDRESS(ROW()+1,COLUMN(), 4)),Dex!$A$2:$C449,3,false),"")} | F26: {=iferror(VLOOKUP(INDIRECT(ADDRESS(ROW()+1,COLUMN(), 4)),Dex!$A$2:$C449,3,false),"")} | G26: {=iferror(VLOOKUP(INDIRECT(ADDRESS(ROW()+1,COLUMN(), 4)),Dex!$A$2:$C449,3,false),"")} | H26: {=iferror(VLOOKUP("TRAINER_PIC_Magma_Grunt_F",Sprites!$A$1:$B449,2,false),"")}
B27: Nidoking | C27: Scream Tail | D27: Rhydon | E27: Simisear
A28: Level | B28: 61 | C28: 62 | D28: 61 | E28: 61
A29: Held Item | B29: King's Rock | C29: Booster Energy | D29: Bright Powder | E29: Focus Band
A30: Ability | B30: Poison Point | C30: Protosynthesis | D30: Reckless | E30: Blaze
A31: Nature | B31: Jolly | C31: Modest | D31: Adamant | E31: Timid
A32: Moves | B32: Rock Blast | C32: Misty Explosion | D32: Head Smash | E32: Flamethrower
B33: Poison Jab | D33: Stealth Rock | E33: Fire Spin
B34: Fire Punch | D34: Drill Run | E34: Endeavor
B35: Sucker Punch | D35: Double-Edge | E35: Grass Knot
A36: Name | B36: Land Cave Team Magma Grunt #4
A37: Pokémon | B37: {=iferror(VLOOKUP(INDIRECT(ADDRESS(ROW()+1,COLUMN(), 4)),Dex!$A$2:$C449,3,false),"")} | C37: {=iferror(VLOOKUP(INDIRECT(ADDRESS(ROW()+1,COLUMN(), 4)),Dex!$A$2:$C449,3,false),"")} | D37: {=iferror(VLOOKUP(INDIRECT(ADDRESS(ROW()+1,COLUMN(), 4)),Dex!$A$2:$C449,3,false),"")} | E37: {=iferror(VLOOKUP(INDIRECT(ADDRESS(ROW()+1,COLUMN(), 4)),Dex!$A$2:$C449,3,false),"")} | F37: {=iferror(VLOOKUP(INDIRECT(ADDRESS(ROW()+1,COLUMN(), 4)),Dex!$A$2:$C449,3,false),"")} | G37: {=iferror(VLOOKUP(INDIRECT(ADDRESS(ROW()+1,COLUMN(), 4)),Dex!$A$2:$C449,3,false),"")} | H37: {=iferror(VLOOKUP("TRAINER_PIC_Magma_Grunt_M",Sprites!$A$1:$B449,2,false),"")}
B38: Skuntank | C38: Falinks | D38: Charizard | E38: Emboar
A39: Level | B39: 61 | C39: 62 | D39: 62 | E39: 62
A40: Held Item | B40: Rowap Berry | C40: Leftovers | D40: Heavy-Duty Boots | E40: Quick Claw
A41: Ability | B41: Aftermath | C41: Battle Armor | D41: Blaze | E41: Reckless
...

Sheet Flannery Split
A2: Route 111
A3: Name | B3: Winstrate Victor
A4: Pokémon | B4: {=iferror(VLOOKUP(INDIRECT(ADDRESS(ROW()+1,COLUMN(), 4)),Dex!$A$2:$C526,3,false),"")} | C4: {=iferror(VLOOKUP(INDIRECT(ADDRESS(ROW()+1,COLUMN(), 4)),Dex!$A$2:$C526,3,false),"")} | D4: {=iferror(VLOOKUP(INDIRECT(ADDRESS(ROW()+1,COLUMN(), 4)),Dex!$A$2:$C526,3,false),"")} | E4: {=iferror(VLOOKUP(INDIRECT(ADDRESS(ROW()+1,COLUMN(), 4)),Dex!$A$2:$C526,3,false),"")} | F4: {=iferror(VLOOKUP(INDIRECT(ADDRESS(ROW()+1,COLUMN(), 4)),Dex!$A$2:$C526,3,false),"")} | G4: {=iferror(VLOOKUP(INDIRECT(ADDRESS(ROW()+1,COLUMN(), 4)),Dex!$A$2:$C526,3,false),"")} | H4: {=iferror(VLOOKUP("TRAINER_PIC_Pokefan_M",Sprites!$A$1:$B526,2,false),"")}
B5: Linoone | C5: Obstagoon
A6: Level | B6: 66 | C6: 66
A7: Held Item | B7: Toxic Orb | C7: Flame Orb
A8: Ability | B8: Quick Feet | C8: Guts
A9: Nature | B9: Adamant | C9: Adamant
A10: Moves | B10: Protect | C10: Obstruct
B11: Facade | C11: Sucker Punch
B12: Belly Drum | C12: Knock Off
B13: Extreme Speed | C13: Facade
A14: Name | B14: Winstrate Victoria
A15: Pokémon | B15: {=iferror(VLOOKUP(INDIRECT(ADDRESS(ROW()+1,COLUMN(), 4)),Dex!$A$2:$C526,3,false),"")} | C15: {=iferror(VLOOKUP(INDIRECT(ADDRESS(ROW()+1,COLUMN(), 4)),Dex!$A$2:$C526,3,false),"")} | D15: {=iferror(VLOOKUP(INDIRECT(ADDRESS(ROW()+1,COLUMN(), 4)),Dex!$A$2:$C526,3,false),"")} | E15: {=iferror(VLOOKUP(INDIRECT(ADDRESS(ROW()+1,COLUMN(), 4)),Dex!$A$2:$C526,3,false),"")} | F15: {=iferror(VLOOKUP(INDIRECT(ADDRESS(ROW()+1,COLUMN(), 4)),Dex!$A$2:$C526,3,false),"")} | G15: {=iferror(VLOOKUP(INDIRECT(ADDRESS(ROW()+1,COLUMN(), 4)),Dex!$A$2:$C526,3,false),"")} | H15: {=iferror(VLOOKUP("TRAINER_PIC_Pokefan_F",Sprites!$A$1:$B526,2,false),"")}
B16: Roserade | C16: Blissey | D16: Vespiquen
A17: Level | B17: 66 | C17: 66 | D17: 67
A18: Held Item | B18: Grass Gem | C18: Leftovers | D18: Leftovers
A19: Ability | B19: Poison Point | C19: Natural Cure | D19: Pressure
A20: Nature | B20: Timid | C20: Bold | D20: Relaxed
A21: Moves | B21: Leaf Storm | C21: Hyper Voice | D21: Infestation
B22: Sludge Bomb | C22: Seismic Toss | D22: Heal Order
B23: Synthesis | C23: Protect | D23: Toxic
B24: Water Sport | C24: Soft-Boiled | D24: Attack Order
A25: Name | B25: Winstrate Vivi
A26: Pokémon | B26: {=iferror(VLOOKUP(INDIRECT(ADDRESS(ROW()+1,COLUMN(), 4)),Dex!$A$2:$C526,3,false),"")} | C26: {=iferror(VLOOKUP(INDIRECT(ADDRESS(ROW()+1,COLUMN(), 4)),Dex!$A$2:$C526,3,false),"")} | D26: {=iferror(VLOOKUP(INDIRECT(ADDRESS(ROW()+1,COLUMN(), 4)),Dex!$A$2:$C526,3,false),"")} | E26: {=iferror(VLOOKUP(INDIRECT(ADDRESS(ROW()+1,COLUMN(), 4)),Dex!$A$2:$C526,3,false),"")} | F26: {=iferror(VLOOKUP(INDIRECT(ADDRESS(ROW()+1,COLUMN(), 4)),Dex!$A$2:$C526,3,false),"")} | G26: {=iferror(VLOOKUP(INDIRECT(ADDRESS(ROW()+1,COLUMN(), 4)),Dex!$A$2:$C526,3,false),"")} | H26: {=iferror(VLOOKUP("TRAINER_PIC_Lass",Sprites!$A$1:$B526,2,false),"")}
B27: Vivillon | C27: Azumarill | D27: Breloom
A28: Level | B28: 67 | C28: 66 | D28: 66
A29: Held Item | B29: Wacan Berry | C29: Shell Bell | D29: Toxic Orb
A30: Ability | B30: Shield Dust | C30: Huge Power | D30: Poison Heal
A31: Nature | B31: Timid | C31: Jolly | D31: Jolly
A32: Moves | B32: Powder | C32: Aqua Tail | D32: Drain Punch
B33: Sleep Powder | C33: Play Rough | D33: Spore
B34: Bug Buzz | C34: Superpower | D34: Rock Slide
B35: Tailwind | C35: Ice Spinner | D35: Substitute
A36: Name | B36: Winstrate Vicky
A37: Pokémon | B37: {=iferror(VLOOKUP(INDIRECT(ADDRESS(ROW()+1,COLUMN(), 4)),Dex!$A$2:$C526,3,false),"")} | C37: {=iferror(VLOOKUP(INDIRECT(ADDRESS(ROW()+1,COLUMN(), 4)),Dex!$A$2:$C526,3,false),"")} | D37: {=iferror(VLOOKUP(INDIRECT(ADDRESS(ROW()+1,COLUMN(), 4)),Dex!$A$2:$C526,3,false),"")} | E37: {=iferror(VLOOKUP(INDIRECT(ADDRESS(ROW()+1,COLUMN(), 4)),Dex!$A$2:$C526,3,false),"")} | F37: {=iferror(VLOOKUP(INDIRECT(ADDRESS(ROW()+1,COLUMN(), 4)),Dex!$A$2:$C526,3,false),"")} | G37: {=iferror(VLOOKUP(INDIRECT(ADDRESS(ROW()+1,COLUMN(), 4)),Dex!$A$2:$C526,3,false),"")} | H37: {=iferror(VLOOKUP("TRAINER_PIC_Expert_F",Sprites!$A$1:$B526,2,false),"")}
B38: Camerupt | C38: Vigoroth | D38: Lilligant-Hisui | E38: Vaporeon | F38: Victini | G38: Medicham-Mega
A39: Level | B39: 67 | C39: 67 | D39: 68 | E39: 67 | F39: 69 | G39: 70
A40: Held Item | B40: Sitrus Berry | C40: Choice Band | D40: Wide Lens | E40: Leftovers | F40: Bug Gem | G40: Medichamite
A41: Ability | B41: Solid Rock | C41: Vital Spirit | D41: Hustle | E41: Water Absorb | F41: Victory Star | G41: Pure Power
...

Sheet Winona Split
A2: Route 118
A3: Name | B3: Fisherman Ordeaux
A4: Pokémon | B4: {=iferror(VLOOKUP(INDIRECT(ADDRESS(ROW()+1,COLUMN(), 4)),Dex!$A$2:$C493,3,false),"")} | C4: {=iferror(VLOOKUP(INDIRECT(ADDRESS(ROW()+1,COLUMN(), 4)),Dex!$A$2:$C493,3,false),"")} | D4: {=iferror(VLOOKUP(INDIRECT(ADDRESS(ROW()+1,COLUMN(), 4)),Dex!$A$2:$C493,3,false),"")} | E4: {=iferror(VLOOKUP(INDIRECT(ADDRESS(ROW()+1,COLUMN(), 4)),Dex!$A$2:$C493,3,false),"")} | F4: {=iferror(VLOOKUP(INDIRECT(ADDRESS(ROW()+1,COLUMN(), 4)),Dex!$A$2:$C493,3,false),"")} | G4: {=iferror(VLOOKUP(INDIRECT(ADDRESS(ROW()+1,COLUMN(), 4)),Dex!$A$2:$C493,3,false),"")} | H4: {=iferror(VLOOKUP("TRAINER_PIC_Fisherman",Sprites!$A$1:$B493,2,false),"")}
B5: Empoleon | C5: Dragonite | D5: Dhelmise | E5: Tatsugiri-Mega
A6: Level | B6: 73 | C6: 74 | D6: 73 | E6: 73
A7: Held Item | B7: Custap Berry | C7: Binding Band | D7: Grip Claw | E7: Tatsugirinite
A8: Ability | B8: Torrent | C8: Multiscale | D8: Steelworker | E8: Speed Boost
A9: Nature | B9: Modest | C9: Jolly | D9: Adamant | E9: Modest
A10: Moves | B10: Stealth Rock | C10: Protect | D10: Phantom Force | E10: Nasty Plot
B11: Make It Rain | C11: Roost | D11: Power Whip | E11: Hydro Pump
B12: Hydro Pump | C12: Fly | D12: Anchor Shot | E12: Dragon Pulse
B13: Grass Knot | C13: Whirlpool | D13: Whirlpool | E13: Thunderbolt
A14: Route 108
A15: Name | B15: Cooltrainer Carolina & Sailor Cory [Double]
A16: Pokémon | B16: {=iferror(VLOOKUP(INDIRECT(ADDRESS(ROW()+1,COLUMN(), 4)),Dex!$A$2:$C493,3,false),"")} | C16: {=iferror(VLOOKUP(INDIRECT(ADDRESS(ROW()+1,COLUMN(), 4)),Dex!$A$2:$C493,3,false),"")} | D16: {=iferror(VLOOKUP(INDIRECT(ADDRESS(ROW()+1,COLUMN(), 4)),Dex!$A$2:$C493,3,false),"")} | E16: {=iferror(VLOOKUP(INDIRECT(ADDRESS(ROW()+1,COLUMN(), 4)),Dex!$A$2:$C493,3,false),"")} | F16: {=iferror(VLOOKUP(INDIRECT(ADDRESS(ROW()+1,COLUMN(), 4)),Dex!$A$2:$C493,3,false),"")} | G16: {=iferror(VLOOKUP(INDIRECT(ADDRESS(ROW()+1,COLUMN(), 4)),Dex!$A$2:$C493,3,false),"")} | H16: {=iferror(VLOOKUP("TRAINER_PIC_Cooltrainer_F",Sprites!$A$1:$B493,2,false),"")}
B17: Tatsugiri | C17: Dracovish | E17: Dondozo | F17: Feraligatr-Mega
A18: Level | B18: 73 | C18: 73 | E18: 73 | F18: 74
A19: Held Item | B19: Sitrus Berry | C19: Mystic Water | E19: Covert Cloak | F19: Feraligite
A20: Ability | B20: Commander | C20: Strong Jaw | E20: Oblivious | F20: Dragon's Maw
A21: Nature | B21: Timid | C21: Jolly | E21: Jolly | F21: Adamant
A22: Moves | B22: Hydro Pump | C22: Fishious Rend | E22: Order Up | F22: Scale Shot
B23: Dragon Pulse | C23: Crunch | E23: Liquidation | F23: Liquidation
B24: Surf | C24: Psychic Fangs | E24: Body Press | F24: Gunk Shot
B25: Dragon Cheer | C25: Dragon Cheer | E25: Heavy Slam | F25: Dragon Cheer
A26: Abandoned Ship
A27: Name | B27: Rich Boy Milky
A28: Pokémon | B28: {=iferror(VLOOKUP(INDIRECT(ADDRESS(ROW()+1,COLUMN(), 4)),Dex!$A$2:$C493,3,false),"")} | C28: {=iferror(VLOOKUP(INDIRECT(ADDRESS(ROW()+1,COLUMN(), 4)),Dex!$A$2:$C493,3,false),"")} | D28: {=iferror(VLOOKUP(INDIRECT(ADDRESS(ROW()+1,COLUMN(), 4)),Dex!$A$2:$C493,3,false),"")} | E28: {=iferror(VLOOKUP(INDIRECT(ADDRESS(ROW()+1,COLUMN(), 4)),Dex!$A$2:$C493,3,false),"")} | F28: {=iferror(VLOOKUP(INDIRECT(ADDRESS(ROW()+1,COLUMN(), 4)),Dex!$A$2:$C493,3,false),"")} | G28: {=iferror(VLOOKUP(INDIRECT(ADDRESS(ROW()+1,COLUMN(), 4)),Dex!$A$2:$C493,3,false),"")} | H28: {=iferror(VLOOKUP("TRAINER_PIC_RichBoy",Sprites!$A$1:$B493,2,false),"")}
B29: Porygon2 | C29: Espathra | D29: Cinccino | E29: Durant | F29: Falinks-Mega
A30: Level | B30: 73 | C30: 73 | D30: 73 | E30: 74 | F30: 73
A31: Held Item | B31: Eviolite | C31: Light Clay | D31: Clear Amulet | E31: Muscle Band | F31: Falinksite
A32: Ability | B32: Trace | C32: Speed Boost | D32: Skill Link | E32: Hustle | F32: Sharpness
A33: Nature | B33: Bold | C33: Timid | D33: Jolly | E33: Adamant | F33: Adamant
A34: Moves | B34: Tri Attack | C34: Reflect | D34: Tail Slap | E34: First Impression | F34: Sacred Sword
B35: Thunderbolt | C35: Light Screen | D35: Knock Off | E35: Leech Life | F35: No Retreat
B36: Recover | C36: Psychic | D36: Baton Pass | E36: Iron Head | F36: Night Slash
B37: Thunder Wave | C37: Baton Pass | D37: Tidy Up | E37: Stomping Tantrum | F37: Psycho Cut
A38: Name | B38: Sailor Duncan
A39: Pokémon | B39: {=iferror(VLOOKUP(INDIRECT(ADDRESS(ROW()+1,COLUMN(), 4)),Dex!$A$2:$C493,3,false),"")} | C39: {=iferror(VLOOKUP(INDIRECT(ADDRESS(ROW()+1,COLUMN(), 4)),Dex!$A$2:$C493,3,false),"")} | D39: {=iferror(VLOOKUP(INDIRECT(ADDRESS(ROW()+1,COLUMN(), 4)),Dex!$A$2:$C493,3,false),"")} | E39: {=iferror(VLOOKUP(INDIRECT(ADDRESS(ROW()+1,COLUMN(), 4)),Dex!$A$2:$C493,3,false),"")} | F39: {=iferror(VLOOKUP(INDIRECT(ADDRESS(ROW()+1,COLUMN(), 4)),Dex!$A$2:$C493,3,false),"")} | G39: {=iferror(VLOOKUP(INDIRECT(ADDRESS(ROW()+1,COLUMN(), 4)),Dex!$A$2:$C493,3,false),"")} | H39: {=iferror(VLOOKUP("TRAINER_PIC_Sailor",Sprites!$A$1:$B493,2,false),"")}
B40: Jellicent | C40: Crabominable | D40: Reuniclus | E40: Ursaluna | F40: Scolipede-Mega
A41: Level | B41: 73 | C41: 73 | D41: 73 (Burn) | E41: 74 (Burn) | F41: 74
...

Sheet Tate&Liza Split
A2: Route 120
A3: Name | B3: Rogue Kecleon
A4: Pokémon | B4: {=iferror(VLOOKUP(INDIRECT(ADDRESS(ROW()+1,COLUMN(), 4)),Dex!$A$2:$C671,3,false),"")} | C4: {=iferror(VLOOKUP(INDIRECT(ADDRESS(ROW()+1,COLUMN(), 4)),Dex!$A$2:$C671,3,false),"")} | D4: {=iferror(VLOOKUP(INDIRECT(ADDRESS(ROW()+1,COLUMN(), 4)),Dex!$A$2:$C671,3,false),"")} | E4: {=iferror(VLOOKUP(INDIRECT(ADDRESS(ROW()+1,COLUMN(), 4)),Dex!$A$2:$C671,3,false),"")} | F4: {=iferror(VLOOKUP(INDIRECT(ADDRESS(ROW()+1,COLUMN(), 4)),Dex!$A$2:$C671,3,false),"")} | G4: {=iferror(VLOOKUP(INDIRECT(ADDRESS(ROW()+1,COLUMN(), 4)),Dex!$A$2:$C671,3,false),"")} | H4: {=iferror(VLOOKUP("TRAINER_PIC_Kecleon",Sprites!$A$1:$B671,2,false),"")}
B5: Kecleon
A6: Level | B6: 80
A7: Held Item | B7: None
A8: Ability | B8: Libero
A9: Nature | B9: Adamant
A10: Moves | B10: Shadow Sneak
B11: Low Kick
B12: Knock Off
B13: Return
A14: Name | B14: Cooltrainer Abobo
A15: Pokémon | B15: {=iferror(VLOOKUP(INDIRECT(ADDRESS(ROW()+1,COLUMN(), 4)),Dex!$A$2:$C671,3,false),"")} | C15: {=iferror(VLOOKUP(INDIRECT(ADDRESS(ROW()+1,COLUMN(), 4)),Dex!$A$2:$C671,3,false),"")} | D15: {=iferror(VLOOKUP(INDIRECT(ADDRESS(ROW()+1,COLUMN(), 4)),Dex!$A$2:$C671,3,false),"")} | E15: {=iferror(VLOOKUP(INDIRECT(ADDRESS(ROW()+1,COLUMN(), 4)),Dex!$A$2:$C671,3,false),"")} | F15: {=iferror(VLOOKUP(INDIRECT(ADDRESS(ROW()+1,COLUMN(), 4)),Dex!$A$2:$C671,3,false),"")} | G15: {=iferror(VLOOKUP(INDIRECT(ADDRESS(ROW()+1,COLUMN(), 4)),Dex!$A$2:$C671,3,false),"")} | H15: {=iferror(VLOOKUP("TRAINER_PIC_Cooltrainer_M",Sprites!$A$1:$B671,2,false),"")}
B16: Alakazam | C16: Swellow | D16: Magnezone | E16: Ribombee | F16: Dugtrio
A17: Level | B17: 78 | C17: 79 (Burn) | D17: 79 | E17: 78 | F17: 78
A18: Held Item | B18: Focus Sash | C18: Life Orb | D18: Expert Belt | E18: Coba Berry | F18: Ground Gem
A19: Ability | B19: Inner Focus | C19: Guts | D19: Magnet Pull | E19: Shield Dust | F19: Arena Trap
A20: Nature | B20: Timid | C20: Jolly | D20: Bold | E20: Timid | F20: Jolly
A21: Moves | B21: Psychic | C21: Facade | D21: Thunder Wave | E21: Magic Room | F21: Earthquake
B22: Future Sight | C22: Reversal | D22: Flash Cannon | E22: Moonblast | F22: Stone Edge
B23: Magic Room | C23: Brave Bird | D23: Body Press | E23: Bug Buzz | F23: Throat Chop
B24: Focus Blast | C24: U-Turn | D24: Volt Switch | E24: Baton Pass | F24: Swords Dance
A25: Name | B25: Parasol Lady Angelica
A26: Pokémon | B26: {=iferror(VLOOKUP(INDIRECT(ADDRESS(ROW()+1,COLUMN(), 4)),Dex!$A$2:$C671,3,false),"")} | C26: {=iferror(VLOOKUP(INDIRECT(ADDRESS(ROW()+1,COLUMN(), 4)),Dex!$A$2:$C671,3,false),"")} | D26: {=iferror(VLOOKUP(INDIRECT(ADDRESS(ROW()+1,COLUMN(), 4)),Dex!$A$2:$C671,3,false),"")} | E26: {=iferror(VLOOKUP(INDIRECT(ADDRESS(ROW()+1,COLUMN(), 4)),Dex!$A$2:$C671,3,false),"")} | F26: {=iferror(VLOOKUP(INDIRECT(ADDRESS(ROW()+1,COLUMN(), 4)),Dex!$A$2:$C671,3,false),"")} | G26: {=iferror(VLOOKUP(INDIRECT(ADDRESS(ROW()+1,COLUMN(), 4)),Dex!$A$2:$C671,3,false),"")} | H26: {=iferror(VLOOKUP("TRAINER_PIC_Parasol_Lady",Sprites!$A$1:$B671,2,false),"")}
B27: Mimikyu | C27: Cradily | D27: Dracovish | E27: Blaziken | F27: Greninja-Mega
A28: Level | B28: 78 | C28: 78 | D28: 78 | E28: 79 | F28: 79
A29: Held Item | B29: Spell Tag | C29: Grip Claw | D29: Choice Scarf | E29: White Herb | F29: Greninjite
A30: Ability | B30: Disguise | C30: Storm Drain | D30: Strong Jaw | E30: Speed Boost | F30: Sniper
A31: Nature | B31: Jolly | C31: Bold | D31: Adamant | E31: Adamant | F31: Naive
A32: Moves | B32: Swords Dance | C32: Giga Drain | D32: Fishious Rend | E32: Flare Blitz | F32: Water Shuriken
B33: Play Rough | C33: Ancient Power | D33: Outrage | E33: Close Combat | F33: Night Slash
B34: Shadow Claw | C34: Recover | D34: Psychic Fangs | E34: Swords Dance | F34: Gunk Shot
B35: Shadow Sneak | C35: Sand Tomb | D35: Crunch | E35: Detect | F35: Focus Energy
A36: Name | B36: Ninja Boy Alex
A37: Pokémon | B37: {=iferror(VLOOKUP(INDIRECT(ADDRESS(ROW()+1,COLUMN(), 4)),Dex!$A$2:$C671,3,false),"")} | C37: {=iferror(VLOOKUP(INDIRECT(ADDRESS(ROW()+1,COLUMN(), 4)),Dex!$A$2:$C671,3,false),"")} | D37: {=iferror(VLOOKUP(INDIRECT(ADDRESS(ROW()+1,COLUMN(), 4)),Dex!$A$2:$C671,3,false),"")} | E37: {=iferror(VLOOKUP(INDIRECT(ADDRESS(ROW()+1,COLUMN(), 4)),Dex!$A$2:$C671,3,false),"")} | F37: {=iferror(VLOOKUP(INDIRECT(ADDRESS(ROW()+1,COLUMN(), 4)),Dex!$A$2:$C671,3,false),"")} | G37: {=iferror(VLOOKUP(INDIRECT(ADDRESS(ROW()+1,COLUMN(), 4)),Dex!$A$2:$C671,3,false),"")} | H37: {=iferror(VLOOKUP("TRAINER_PIC_Ninja_Boy",Sprites!$A$1:$B671,2,false),"")}
B38: Kecleon | C38: Yanmega | D38: Lucario | E38: Gliscor | F38: Zarude
A39: Level | B39: 78 | C39: 78 | D39: 78 | E39: 79 (Poison) | F39: 79
A40: Held Item | B40: Rocky Helmet | C40: Choice Specs | D40: Life Orb | E40: Yache Berry | F40: Snowball
A41: Ability | B41: Libero | C41: Tinted Lens | D41: Steadfast | E41: Poison Heal | F41: Sniper
...

Sheet Steven Split
A2: Space Center
A3: Name | B3: Space Center Team Magma Grunt #1
A4: Pokémon | B4: {=iferror(VLOOKUP(INDIRECT(ADDRESS(ROW()+1,COLUMN(), 4)),Dex!$A$2:$C473,3,false),"")} | C4: {=iferror(VLOOKUP(INDIRECT(ADDRESS(ROW()+1,COLUMN(), 4)),Dex!$A$2:$C473,3,false),"")} | D4: {=iferror(VLOOKUP(INDIRECT(ADDRESS(ROW()+1,COLUMN(), 4)),Dex!$A$2:$C473,3,false),"")} | E4: {=iferror(VLOOKUP(INDIRECT(ADDRESS(ROW()+1,COLUMN(), 4)),Dex!$A$2:$C473,3,false),"")} | F4: {=iferror(VLOOKUP(INDIRECT(ADDRESS(ROW()+1,COLUMN(), 4)),Dex!$A$2:$C473,3,false),"")} | G4: {=iferror(VLOOKUP(INDIRECT(ADDRESS(ROW()+1,COLUMN(), 4)),Dex!$A$2:$C473,3,false),"")} | H4: {=iferror(VLOOKUP("TRAINER_PIC_Magma_Grunt_M",Sprites!$A$1:$B473,2,false),"")}
B5: Glimmora | C5: Blaziken | D5: Magnezone | E5: Alcremie | F5: Blacephalon | G5: Ho-Oh
A6: Level | B6: 87 | C6: 88 | D6: 87 | E6: 87 | F6: 87 | G6: 87
A7: Held Item | B7: Quick Claw | C7: Scope Lens | D7: Custap Berry | E7: Focus Band | F7: Starf Berry | G7: Bright Powder
A8: Ability | B8: Toxic Debris | C8: Speed Boost | D8: Sturdy | E8: Aroma Veil | F8: Beast Boost | G8: Regenerator
A9: Nature | B9: Quiet | C9: Adamant | D9: Quiet | E9: Modest | F9: Timid | G9: Jolly
A10: Moves | B10: Stealth Rock | C10: Blaze Kick | D10: Thunderbolt | E10: Moonblast | F10: Mind Blown | G10: Sacred Fire
B11: Spikes | C11: Cross Chop | D11: Flash Cannon | E11: Mystical Fire | F11: Shadow Ball | G11: Dual Wingbeat
B12: Explosion | C12: Stone Edge | D12: Hidden Power Grass | E12: Psychic | F12: Aura Sphere | G12: Whirlwind
B13: Power Gem | C13: Protect | D13: Explosion | E13: Misty Explosion | F13: Explosion | G13: Revival Blessing
A14: Name | B14: Space Center Team Magma Grunt #2
A15: Pokémon | B15: {=iferror(VLOOKUP(INDIRECT(ADDRESS(ROW()+1,COLUMN(), 4)),Dex!$A$2:$C473,3,false),"")} | C15: {=iferror(VLOOKUP(INDIRECT(ADDRESS(ROW()+1,COLUMN(), 4)),Dex!$A$2:$C473,3,false),"")} | D15: {=iferror(VLOOKUP(INDIRECT(ADDRESS(ROW()+1,COLUMN(), 4)),Dex!$A$2:$C473,3,false),"")} | E15: {=iferror(VLOOKUP(INDIRECT(ADDRESS(ROW()+1,COLUMN(), 4)),Dex!$A$2:$C473,3,false),"")} | F15: {=iferror(VLOOKUP(INDIRECT(ADDRESS(ROW()+1,COLUMN(), 4)),Dex!$A$2:$C473,3,false),"")} | G15: {=iferror(VLOOKUP(INDIRECT(ADDRESS(ROW()+1,COLUMN(), 4)),Dex!$A$2:$C473,3,false),"")} | H15: {=iferror(VLOOKUP("TRAINER_PIC_Magma_Grunt_F",Sprites!$A$1:$B473,2,false),"")}
B16: Flutter Mane | C16: Morpeko | D16: Swoobat | E16: Emboar | F16: Guzzlord | G16: Victini
A17: Level | B17: 87 | C17: 87 | D17: 87 | E17: 88 | F17: 87 | G17: 89
A18: Held Item | B18: Focus Band | C18: Berserk Gene | D18: Kee Berry | E18: Quick Claw | F18: Roseli Berry | G18: White Herb
A19: Ability | B19: Protosynthesis | C19: Hunger Switch | D19: Simple | E19: Reckless | F19: Intimidate | G19: Victory Star
A20: Nature | B20: Timid | C20: Jolly | D20: Timid | E20: Adamant | F20: Adamant | G20: Jolly
A21: Moves | B21: Infernal Parade | C21: Aura Wheel | D21: Calm Mind | E21: Close Combat | F21: Dragon Rush | G21: Victory Dance
B22: Mystical Fire | C22: Nuzzle | D22: Hurricane | E22: Flare Blitz | F22: Knock Off | G22: V-create
B23: Hypnosis | C23: Baton Pass | D23: Stored Power | E23: Head Smash | F23: Iron Tail | G23: Zen Headbutt
B24: Memento | C24: Obstruct | D24: Heat Wave | E24: Yawn | F24: Parting Shot | G24: Bolt Strike
A25: Name | B25: Space Center Team Magma Elite Grunt [Double]
A26: Pokémon | B26: {=iferror(VLOOKUP(INDIRECT(ADDRESS(ROW()+1,COLUMN(), 4)),Dex!$A$2:$C473,3,false),"")} | C26: {=iferror(VLOOKUP(INDIRECT(ADDRESS(ROW()+1,COLUMN(), 4)),Dex!$A$2:$C473,3,false),"")} | D26: {=iferror(VLOOKUP(INDIRECT(ADDRESS(ROW()+1,COLUMN(), 4)),Dex!$A$2:$C473,3,false),"")} | E26: {=iferror(VLOOKUP(INDIRECT(ADDRESS(ROW()+1,COLUMN(), 4)),Dex!$A$2:$C473,3,false),"")} | F26: {=iferror(VLOOKUP(INDIRECT(ADDRESS(ROW()+1,COLUMN(), 4)),Dex!$A$2:$C473,3,false),"")} | G26: {=iferror(VLOOKUP(INDIRECT(ADDRESS(ROW()+1,COLUMN(), 4)),Dex!$A$2:$C473,3,false),"")} | H26: {=iferror(VLOOKUP("TRAINER_PIC_Magma_Grunt_M",Sprites!$A$1:$B473,2,false),"")}
B27: Incineroar | C27: Ursaluna | D27: Watchog | E27: Landorus-Therian | F27: Raging Bolt | G27: Cinderace
A28: Level | B28: 88 | C28: 90 (Burn) | D28: 87 | E28: 91 | F28: 88 | G28: 89
A29: Held Item | B29: Bright Powder | C29: Quick Claw | D29: Focus Band | E29: Covert Cloak | F29: Electric Gem | G29: King's Rock
A30: Ability | B30: Intimidate | C30: Guts | D30: Illuminate | E30: Intimidate | F30: Protosynthesis | G30: Libero
A31: Nature | B31: Adamant | C31: Adamant | D31: Adamant | E31: Careful | F31: Timid | G31: Jolly
A32: Moves | B32: Fake Out | C32: Headlong Rush | D32: Fake Out | E32: High Horsepower | F32: Thunderbolt | G32: Pyro Ball
B33: Flare Blitz | C33: Facade | D33: Super Fang | E33: Floaty Fall | F33: Dragon Pulse | G33: Close Combat
B34: Knock Off | C34: Fire Punch | D34: Fire Punch | E34: Stealth Rock | F34: Thunderclap | G34: Fling
B35: Parting Shot | C35: Feint | D35: Hypnosis | E35: Stone Edge | F35: Sunny Day | G35: Coaching
A36: Name | B36: Space Center Team Magma Cobalt
A37: Pokémon | B37: {=iferror(VLOOKUP(INDIRECT(ADDRESS(ROW()+1,COLUMN(), 4)),Dex!$A$2:$C473,3,false),"")} | C37: {=iferror(VLOOKUP(INDIRECT(ADDRESS(ROW()+1,COLUMN(), 4)),Dex!$A$2:$C473,3,false),"")} | D37: {=iferror(VLOOKUP(INDIRECT(ADDRESS(ROW()+1,COLUMN(), 4)),Dex!$A$2:$C473,3,false),"")} | E37: {=iferror(VLOOKUP(INDIRECT(ADDRESS(ROW()+1,COLUMN(), 4)),Dex!$A$2:$C473,3,false),"")} | F37: {=iferror(VLOOKUP(INDIRECT(ADDRESS(ROW()+1,COLUMN(), 4)),Dex!$A$2:$C473,3,false),"")} | G37: {=iferror(VLOOKUP(INDIRECT(ADDRESS(ROW()+1,COLUMN(), 4)),Dex!$A$2:$C473,3,false),"")} | H37: {=iferror(VLOOKUP("TRAINER_PIC_Magma_Grunt_M",Sprites!$A$1:$B473,2,false),"")}
B38: Cobalion | C38: Froslass | D38: Dragonite | E38: Lopunny-Mega
A39: Level | B39: 88 | C39: 87 | D39: 88 | E39: 91
A40: Held Item | B40: Leftovers | C40: Eject Button | D40: Heavy-Duty Boots | E40: Lopunnite
A41: Ability | B41: Inner Focus | C41: Cursed Body | D41: Multiscale | E41: Scrappy
...

Sheet Victory Road Split
A2: Evergrande City
A3: Name | B3: Lorekeeper Zinnia
A4: Pokémon | B4: {=iferror(VLOOKUP(INDIRECT(ADDRESS(ROW()+1,COLUMN(), 4)),Dex!$A$2:$C335,3,false),"")} | C4: {=iferror(VLOOKUP(INDIRECT(ADDRESS(ROW()+1,COLUMN(), 4)),Dex!$A$2:$C335,3,false),"")} | D4: {=iferror(VLOOKUP(INDIRECT(ADDRESS(ROW()+1,COLUMN(), 4)),Dex!$A$2:$C335,3,false),"")} | E4: {=iferror(VLOOKUP(INDIRECT(ADDRESS(ROW()+1,COLUMN(), 4)),Dex!$A$2:$C335,3,false),"")} | F4: {=iferror(VLOOKUP(INDIRECT(ADDRESS(ROW()+1,COLUMN(), 4)),Dex!$A$2:$C335,3,false),"")} | G4: {=iferror(VLOOKUP(INDIRECT(ADDRESS(ROW()+1,COLUMN(), 4)),Dex!$A$2:$C335,3,false),"")} | H4: {=iferror(VLOOKUP("TRAINER_PIC_Zinnia",Sprites!$A$1:$B335,2,false),"")}
B5: Drampa | C5: Exploud | D5: Gyarados | E5: Archaludon | F5: Salamence-Mega | G5: Rayquaza-Mega
A6: Level | B6: 96 | C6: 98 | D6: 97 | E6: 97 | F6: 98 | G6: 95
A7: Held Item | B7: Quick Claw | C7: Life Orb | D7: Wacan Berry | E7: Assault Vest | F7: Iron Ball | G7: White Herb
A8: Ability | B8: Berserk | C8: Scrappy | D8: Intimidate | E8: Stamina | F8: Aerilate | G8: Delta Stream
A9: Nature | B9: Modest | C9: Modest | D9: Jolly | E9: Modest | F9: Adamant | G9: Naive
A10: Moves | B10: Tailwind | C10: Boomburst | D10: Dragon Dance | E10: Draco Meteor | F10: Double-Edge | G10: Dragon Ascent
B11: Boomburst | C11: Focus Blast | D11: Waterfall | E11: Flash Cannon | F11: Earthquake | G11: V-create
B12: Hydro Pump | C12: Whirlpool | D12: Earthquake | E12: Body Press | F12: Tailwind | G12: Extreme Speed
B13: Blizzard | C13: Minimize | D13: Power Whip | E13: Mirror Coat | F13: Roost | G13: Draco Meteor
A14: Route 123
A15: Name | B15: Team Rocket Grunt #1
A16: Pokémon | B16: {=iferror(VLOOKUP(INDIRECT(ADDRESS(ROW()+1,COLUMN(), 4)),Dex!$A$2:$C335,3,false),"")} | C16: {=iferror(VLOOKUP(INDIRECT(ADDRESS(ROW()+1,COLUMN(), 4)),Dex!$A$2:$C335,3,false),"")} | D16: {=iferror(VLOOKUP(INDIRECT(ADDRESS(ROW()+1,COLUMN(), 4)),Dex!$A$2:$C335,3,false),"")} | E16: {=iferror(VLOOKUP(INDIRECT(ADDRESS(ROW()+1,COLUMN(), 4)),Dex!$A$2:$C335,3,false),"")} | F16: {=iferror(VLOOKUP(INDIRECT(ADDRESS(ROW()+1,COLUMN(), 4)),Dex!$A$2:$C335,3,false),"")} | G16: {=iferror(VLOOKUP(INDIRECT(ADDRESS(ROW()+1,COLUMN(), 4)),Dex!$A$2:$C335,3,false),"")} | H16: {=iferror(VLOOKUP("TRAINER_PIC_Rocket_Grunt_M",Sprites!$A$1:$B335,2,false),"")}
B17: Butterfree | C17: Muk | D17: Heatmor | E17: Gogoat | F17: Vaporeon | G17: Golisopod-Mega
A18: Level | B18: 96 | C18: 96 | D18: 96 | E18: 96 | F18: 96 | G18: 97
A19: Held Item | B19: Rowap Berry | C19: Payapa Berry | D19: Power Herb | E19: Leftovers | F19: Focus Band | G19: Golisopite
A20: Ability | B20: Tinted Lens | C20: Poison Touch | D20: Flash Fire | E20: Sap Sipper | F20: Water Absorb | G20: Water Bubble
A21: Nature | B21: Timid | C21: Adamant | D21: Modest | E21: Impish | F21: Sassy | G21: Adamant
A22: Moves | B22: Sleep Powder | C22: Poison Jab | D22: Inferno | E22: Horn Leech | F22: Protect | G22: First Impression
B23: Powder | C23: Fire Punch | D23: Solar Beam | E23: Iron Tail | F23: Perish Song | G23: Jet Punch
B24: Silk Trap | C24: Toxic Spikes | D24: Dig | E24: Protect | F24: Whirlpool | G24: Hard Press
B25: Hurricane | C25: Explosion | D25: Burning Bulwark | E25: Milk Drink | F25: Scald | G25: Swords Dance
A26: Name | B26: Team Rocket Grunt #2
A27: Pokémon | B27: {=iferror(VLOOKUP(INDIRECT(ADDRESS(ROW()+1,COLUMN(), 4)),Dex!$A$2:$C335,3,false),"")} | C27: {=iferror(VLOOKUP(INDIRECT(ADDRESS(ROW()+1,COLUMN(), 4)),Dex!$A$2:$C335,3,false),"")} | D27: {=iferror(VLOOKUP(INDIRECT(ADDRESS(ROW()+1,COLUMN(), 4)),Dex!$A$2:$C335,3,false),"")} | E27: {=iferror(VLOOKUP(INDIRECT(ADDRESS(ROW()+1,COLUMN(), 4)),Dex!$A$2:$C335,3,false),"")} | F27: {=iferror(VLOOKUP(INDIRECT(ADDRESS(ROW()+1,COLUMN(), 4)),Dex!$A$2:$C335,3,false),"")} | G27: {=iferror(VLOOKUP(INDIRECT(ADDRESS(ROW()+1,COLUMN(), 4)),Dex!$A$2:$C335,3,false),"")} | H27: {=iferror(VLOOKUP("TRAINER_PIC_Rocket_Grunt_M",Sprites!$A$1:$B335,2,false),"")}
B28: Beautifly | C28: Weezing | D28: Sandaconda | E28: Mabosstiff | F28: Klinklang | G28: Garchomp-Mega-Z
A29: Level | B29: 96 | C29: 96 | D29: 96 (Burn) | E29: 96 | F29: 97 | G29: 97
A30: Held Item | B30: Salac Berry | C30: Focus Band | D30: Chesto Berry | E30: Quick Claw | F30: Focus Sash | G30: Garchompite Z
A31: Ability | B31: Swarm | C31: Levitate | D31: Shed Skin | E31: Stakeout | F31: Clear Body | G31: Multiscale
A32: Nature | B32: Timid | C32: Sassy | D32: Careful | E32: Adamant | F32: Adamant | G32: Timid
A33: Moves | B33: Stun Spore | C33: Gunk Shot | D33: High Horsepower | E33: Knock Off | F33: Shift Gear | G33: Draco Meteor
B34: Bug Buzz | C34: Fire Blast | D34: Rock Slide | E34: Pursuit | F34: Gear Grind | G34: Surf
B35: Endure | C35: Pain Split | D35: Coil | E35: Play Rough | F35: Earthquake | G35: Substitute
B36: Energy Ball | C36: Explosion | D36: Rest | E36: Destiny Bond | F36: Stone Edge | G36: Laser Focus
A37: Name | B37: Team Rocket Grunt #3
A38: Pokémon | B38: {=iferror(VLOOKUP(INDIRECT(ADDRESS(ROW()+1,COLUMN(), 4)),Dex!$A$2:$C335,3,false),"")} | C38: {=iferror(VLOOKUP(INDIRECT(ADDRESS(ROW()+1,COLUMN(), 4)),Dex!$A$2:$C335,3,false),"")} | D38: {=iferror(VLOOKUP(INDIRECT(ADDRESS(ROW()+1,COLUMN(), 4)),Dex!$A$2:$C335,3,false),"")} | E38: {=iferror(VLOOKUP(INDIRECT(ADDRESS(ROW()+1,COLUMN(), 4)),Dex!$A$2:$C335,3,false),"")} | F38: {=iferror(VLOOKUP(INDIRECT(ADDRESS(ROW()+1,COLUMN(), 4)),Dex!$A$2:$C335,3,false),"")} | G38: {=iferror(VLOOKUP(INDIRECT(ADDRESS(ROW()+1,COLUMN(), 4)),Dex!$A$2:$C335,3,false),"")} | H38: {=iferror(VLOOKUP("TRAINER_PIC_Rocket_Grunt_M",Sprites!$A$1:$B335,2,false),"")}
B39: Dustox | C39: Swalot | D39: Zangoose | E39: Tauros | F39: Crustle | G39: Magearna-Mega
A40: Level | B40: 96 | C40: 96 | D40: 97 (Poison) | E40: 97 | F40: 97 | G40: 98
A41: Held Item | B41: Coba Berry | C41: Starf Berry | D41: Bright Powder | E41: Normal Gem | F41: Quick Claw | G41: Magearnite
...

Sheet Pokémon League
A2: Pokémon League
A3: Name | B3: Elite Four Sidney Singles
A4: Pokémon | B4: {=iferror(VLOOKUP(INDIRECT(ADDRESS(ROW()+1,COLUMN(), 4)),Dex!$A$2:$C101,3,false),"")} | C4: {=iferror(VLOOKUP(INDIRECT(ADDRESS(ROW()+1,COLUMN(), 4)),Dex!$A$2:$C101,3,false),"")} | D4: {=iferror(VLOOKUP(INDIRECT(ADDRESS(ROW()+1,COLUMN(), 4)),Dex!$A$2:$C101,3,false),"")} | E4: {=iferror(VLOOKUP(INDIRECT(ADDRESS(ROW()+1,COLUMN(), 4)),Dex!$A$2:$C101,3,false),"")} | F4: {=iferror(VLOOKUP(INDIRECT(ADDRESS(ROW()+1,COLUMN(), 4)),Dex!$A$2:$C101,3,false),"")} | G4: {=iferror(VLOOKUP(INDIRECT(ADDRESS(ROW()+1,COLUMN(), 4)),Dex!$A$2:$C101,3,false),"")} | H4: {=iferror(VLOOKUP("TRAINER_PIC_Elite_Four_Sidney",Sprites!$A$1:$B101,2,false),"")}
B5: Greninja-Mega | C5: Overqwil | D5: Grimmsnarl | E5: Chi Yu | F5: Yveltal | G5: Kingambit
A6: Level | B6: 100 | C6: 100 | D6: 100 | E6: 100 | F6: 100 | G6: 100
A7: Held Item | B7: Greninjite | C7: Assault Vest | D7: Light Clay | E7: Heavy-Duty Boots | F7: Black Glasses | G7: Chople Berry
A8: Ability | B8: Sniper | C8: Intimidate | D8: Prankster | E8: Beads of Ruin | F8: Dark Aura | G8: Supreme Overlord
A9: Nature | B9: Timid | C9: Adamant | D9: Impish | E9: Timid | F9: Timid | G9: Brave
A10: Moves | B10: Water Shuriken | C10: Gunk Shot | D10: Reflect | E10: Flamethrower | F10: Dark Pulse | G10: Knock Off
B11: Night Daze | C11: Crunch | D11: Light Screen | E11: Fiery Wrath | F11: Oblivion Wing | G11: Sucker Punch
B12: Spikes | C12: Liquidation | D12: Spirit Break | E12: Flame Charge | F12: Heat Wave | G12: Iron Head
B13: Toxic Spikes | C13: Explosion | D13: Parting Shot | E13: Nasty Plot | F13: Disable | G13: Swords Dance
A14: Name | B14: Elite Four Sidney Doubles [Double]
A15: Pokémon | B15: {=iferror(VLOOKUP(INDIRECT(ADDRESS(ROW()+1,COLUMN(), 4)),Dex!$A$2:$C101,3,false),"")} | C15: {=iferror(VLOOKUP(INDIRECT(ADDRESS(ROW()+1,COLUMN(), 4)),Dex!$A$2:$C101,3,false),"")} | D15: {=iferror(VLOOKUP(INDIRECT(ADDRESS(ROW()+1,COLUMN(), 4)),Dex!$A$2:$C101,3,false),"")} | E15: {=iferror(VLOOKUP(INDIRECT(ADDRESS(ROW()+1,COLUMN(), 4)),Dex!$A$2:$C101,3,false),"")} | F15: {=iferror(VLOOKUP(INDIRECT(ADDRESS(ROW()+1,COLUMN(), 4)),Dex!$A$2:$C101,3,false),"")} | G15: {=iferror(VLOOKUP(INDIRECT(ADDRESS(ROW()+1,COLUMN(), 4)),Dex!$A$2:$C101,3,false),"")} | H15: {=iferror(VLOOKUP("TRAINER_PIC_Elite_Four_Sidney",Sprites!$A$1:$B101,2,false),"")}
B16: Scrafty | C16: Chien Pao | D16: Overqwil | E16: Yveltal | F16: Gyarados-Mega | G16: Kingambit
A17: Level | B17: 100 | C17: 100 | D17: 100 | E17: 100 | F17: 100 | G17: 100
A18: Held Item | B18: Covert Cloak | C18: Focus Sash | D18: Assault Vest | E18: Black Glasses | F18: Gyaradosite | G18: Chople Berry
A19: Ability | B19: Intimidate | C19: Sword of Ruin | D19: Intimidate | E19: Dark Aura | F19: Mold Breaker | G19: Supreme Overlord
A20: Nature | B20: Careful | C20: Jolly | D20: Adamant | E20: Timid | F20: Jolly | G20: Adamant
A21: Moves | B21: Fake Out | C21: Mountain Gale | D21: Gunk Shot | E21: Dark Pulse | F21: Dragon Dance | G21: Knock Off
B22: Drain Punch | C22: Throat Chop | D22: Baddy Bad | E22: Oblivion Wing | F22: Liquidation | G22: Sucker Punch
B23: Foul Play | C23: Close Combat | D23: Liquidation | E23: Heat Wave | F23: Crunch | G23: Iron Head
B24: Upper Hand | C24: Protect | D24: Icy Wind | E24: Tailwind | F24: Power Whip | G24: Low Kick
A25: Name | B25: Elite Four Phoebe Singles
A26: Pokémon | B26: {=iferror(VLOOKUP(INDIRECT(ADDRESS(ROW()+1,COLUMN(), 4)),Dex!$A$2:$C101,3,false),"")} | C26: {=iferror(VLOOKUP(INDIRECT(ADDRESS(ROW()+1,COLUMN(), 4)),Dex!$A$2:$C101,3,false),"")} | D26: {=iferror(VLOOKUP(INDIRECT(ADDRESS(ROW()+1,COLUMN(), 4)),Dex!$A$2:$C101,3,false),"")} | E26: {=iferror(VLOOKUP(INDIRECT(ADDRESS(ROW()+1,COLUMN(), 4)),Dex!$A$2:$C101,3,false),"")} | F26: {=iferror(VLOOKUP(INDIRECT(ADDRESS(ROW()+1,COLUMN(), 4)),Dex!$A$2:$C101,3,false),"")} | G26: {=iferror(VLOOKUP(INDIRECT(ADDRESS(ROW()+1,COLUMN(), 4)),Dex!$A$2:$C101,3,false),"")} | H26: {=iferror(VLOOKUP("TRAINER_PIC_Elite_Four_Phoebe",Sprites!$A$1:$B101,2,false),"")}
B27: Zoroark-Hisui | C27: Chandelure-Mega | D27: Sneasler | E27: Flutter Mane | F27: Marowak | G27: Giratina-Origin
A28: Level | B28: 100 | C28: 100 | D28: 100 | E28: 100 | F28: 100 | G28: 100
A29: Held Item | B29: Focus Sash | C29: Chandelurite | D29: Fighting Gem | E29: Booster Energy | F29: Thick Club | G29: Griseous Core
A30: Ability | B30: Illusion | C30: Technician | D30: Unburden | E30: Protosynthesis | F30: Rock Head | G30: Levitate
A31: Nature | B31: Timid | C31: Timid | D31: Jolly | E31: Timid | F31: Brave | G31: Jolly
A32: Moves | B32: Hyper Voice | C32: Fire Blast | D32: Close Combat | E32: Moongeist Beam | F32: Headlong Rush | G32: Dragon Rush
B33: Flamethrower | C33: Ominous Wind | D33: Dire Claw | E33: Moonblast | F33: Head Smash | G33: Iron Tail
B34: Grass Knot | C34: Energy Ball | D34: Knock Off | E34: Mystical Fire | F34: Ice Spinner | G34: Aqua Tail
B35: Memento | C35: Hidden Power Bug | D35: Swords Dance | E35: Calm Mind | F35: Curse | G35: Dragon Dance
A36: Name | B36: Elite Four Phoebe Doubles [Double]
A37: Pokémon | B37: {=iferror(VLOOKUP(INDIRECT(ADDRESS(ROW()+1,COLUMN(), 4)),Dex!$A$2:$C101,3,false),"")} | C37: {=iferror(VLOOKUP(INDIRECT(ADDRESS(ROW()+1,COLUMN(), 4)),Dex!$A$2:$C101,3,false),"")} | D37: {=iferror(VLOOKUP(INDIRECT(ADDRESS(ROW()+1,COLUMN(), 4)),Dex!$A$2:$C101,3,false),"")} | E37: {=iferror(VLOOKUP(INDIRECT(ADDRESS(ROW()+1,COLUMN(), 4)),Dex!$A$2:$C101,3,false),"")} | F37: {=iferror(VLOOKUP(INDIRECT(ADDRESS(ROW()+1,COLUMN(), 4)),Dex!$A$2:$C101,3,false),"")} | G37: {=iferror(VLOOKUP(INDIRECT(ADDRESS(ROW()+1,COLUMN(), 4)),Dex!$A$2:$C101,3,false),"")} | H37: {=iferror(VLOOKUP("TRAINER_PIC_Elite_Four_Phoebe",Sprites!$A$1:$B101,2,false),"")}
B38: Infernape | C38: Gengar-Mega | D38: Sinistcha | E38: Calyrex-Shadow | F38: Marowak | G38: Flutter Mane
A39: Level | B39: 100 | C39: 100 | D39: 100 | E39: 100 | F39: 100 | G39: 100
A40: Held Item | B40: Eject Pack | C40: Gengarite | D40: Lax Inscense | E40: Ghost Gem | F40: Thick Club | G40: Booster Energy
A41: Ability | B41: Blaze | C41: Shadow Tag | D41: Hospitality | E41: As One | F41: Rock Head | G41: Protosynthesis
...
